2025-03-17 23:31:45,857 INFO    StreamThr :33305 [internal.py:wandb_internal():86] W&B internal server running at pid: 33305, started at: 2025-03-17 23:31:45.856885
2025-03-17 23:31:45,858 DEBUG   HandlerThread:33305 [handler.py:handle_request():146] handle_request: status
2025-03-17 23:31:45,864 INFO    WriterThread:33305 [datastore.py:open_for_write():87] open: /Users/ujjwalsingh/Development/dl/DA6401/wandb/run-20250317_233145-m86s5c0y/run-m86s5c0y.wandb
2025-03-17 23:31:45,864 DEBUG   SenderThread:33305 [sender.py:send():379] send: header
2025-03-17 23:31:45,887 DEBUG   SenderThread:33305 [sender.py:send():379] send: run
2025-03-17 23:31:46,648 ERROR   SenderThread:33305 [internal_api.py:execute():373] 403 response executing GraphQL.
2025-03-17 23:31:46,649 ERROR   SenderThread:33305 [internal_api.py:execute():374] {"errors":[{"message":"permission denied","path":["upsertBucket"],"extensions":{"code":"PERMISSION_ERROR"}}],"data":{"upsertBucket":null}}
2025-03-17 23:31:46,649 ERROR   SenderThread:33305 [sender.py:send_run():971] It appears that you do not have permission to access the requested resource. Please reach out to the project owner to grant you access. If you have the correct permissions, verify that there are no issues with your networking setup.(Error 403: Forbidden)
Traceback (most recent call last):
  File "/Users/ujjwalsingh/anaconda3/lib/python3.11/site-packages/wandb/sdk/lib/retry.py", line 131, in __call__
    result = self._call_fn(*args, **kwargs)
             ^^^^^^^^^^^^^^^^^^^^^^^^^^^^^^
  File "/Users/ujjwalsingh/anaconda3/lib/python3.11/site-packages/wandb/sdk/internal/internal_api.py", line 369, in execute
    return self.client.execute(*args, **kwargs)  # type: ignore
           ^^^^^^^^^^^^^^^^^^^^^^^^^^^^^^^^^^^^
  File "/Users/ujjwalsingh/anaconda3/lib/python3.11/site-packages/wandb/vendor/gql-0.2.0/wandb_gql/client.py", line 52, in execute
    result = self._get_result(document, *args, **kwargs)
             ^^^^^^^^^^^^^^^^^^^^^^^^^^^^^^^^^^^^^^^^^^^
  File "/Users/ujjwalsingh/anaconda3/lib/python3.11/site-packages/wandb/vendor/gql-0.2.0/wandb_gql/client.py", line 60, in _get_result
    return self.transport.execute(document, *args, **kwargs)
           ^^^^^^^^^^^^^^^^^^^^^^^^^^^^^^^^^^^^^^^^^^^^^^^^^
  File "/Users/ujjwalsingh/anaconda3/lib/python3.11/site-packages/wandb/sdk/lib/gql_request.py", line 59, in execute
    request.raise_for_status()
  File "/Users/ujjwalsingh/anaconda3/lib/python3.11/site-packages/requests/models.py", line 1021, in raise_for_status
    raise HTTPError(http_error_msg, response=self)
requests.exceptions.HTTPError: 403 Client Error: Forbidden for url: https://api.wandb.ai/graphql

During handling of the above exception, another exception occurred:

Traceback (most recent call last):
  File "/Users/ujjwalsingh/anaconda3/lib/python3.11/site-packages/wandb/sdk/internal/sender.py", line 969, in send_run
    server_run = self._init_run(run, config_value_dict)
                 ^^^^^^^^^^^^^^^^^^^^^^^^^^^^^^^^^^^^^^
  File "/Users/ujjwalsingh/anaconda3/lib/python3.11/site-packages/wandb/sdk/internal/sender.py", line 1014, in _init_run
    server_run, inserted, server_messages = self._api.upsert_run(
                                            ^^^^^^^^^^^^^^^^^^^^^
  File "/Users/ujjwalsingh/anaconda3/lib/python3.11/site-packages/wandb/apis/normalize.py", line 73, in wrapper
    raise err
  File "/Users/ujjwalsingh/anaconda3/lib/python3.11/site-packages/wandb/apis/normalize.py", line 41, in wrapper
    return func(*args, **kwargs)
           ^^^^^^^^^^^^^^^^^^^^^
  File "/Users/ujjwalsingh/anaconda3/lib/python3.11/site-packages/wandb/sdk/internal/internal_api.py", line 2217, in upsert_run
    response = self.gql(
               ^^^^^^^^^
  File "/Users/ujjwalsingh/anaconda3/lib/python3.11/site-packages/wandb/sdk/internal/internal_api.py", line 341, in gql
    ret = self._retry_gql(
          ^^^^^^^^^^^^^^^^
  File "/Users/ujjwalsingh/anaconda3/lib/python3.11/site-packages/wandb/sdk/lib/retry.py", line 147, in __call__
    retry_timedelta_triggered = check_retry_fn(e)
                                ^^^^^^^^^^^^^^^^^
  File "/Users/ujjwalsingh/anaconda3/lib/python3.11/site-packages/wandb/util.py", line 968, in check_retry_fn
    return fallback_retry_fn(e)
           ^^^^^^^^^^^^^^^^^^^^
  File "/Users/ujjwalsingh/anaconda3/lib/python3.11/site-packages/wandb/util.py", line 910, in no_retry_auth
    raise CommError(
wandb.errors.CommError: It appears that you do not have permission to access the requested resource. Please reach out to the project owner to grant you access. If you have the correct permissions, verify that there are no issues with your networking setup.(Error 403: Forbidden)
2025-03-17 23:31:46,848 DEBUG   HandlerThread:33305 [handler.py:handle_request():146] handle_request: shutdown
2025-03-17 23:31:46,849 INFO    HandlerThread:33305 [handler.py:finish():866] shutting down handler
2025-03-17 23:31:46,890 INFO    WriterThread:33305 [datastore.py:close():296] close: /Users/ujjwalsingh/Development/dl/DA6401/wandb/run-20250317_233145-m86s5c0y/run-m86s5c0y.wandb
2025-03-17 23:31:47,664 INFO    SenderThread:33305 [sender.py:finish():1546] shutting down sender
